<?xml version="1.0"?>


<robot name="six_dof_arm" xmlns:xacro="http://ros.org/wiki/xacro">


  <!-- Include materials -->

    <material name="Black">
        <color rgba="0.0 0.0 0.0 1.0"/>
    </material>

    <material name="Red">
        <color rgba="0.8 0.0 0.0 1.0"/>
    </material>

    <material name="White">
        <color rgba="1.0 1.0 1.0 1.0"/>
    </material>


  <xacro:property name="deg_to_rad" value="0.01745329251994329577"/>

  <!-- Constants -->
  <xacro:property name="M_SCALE" value="0.001 0.001 0.001"/> 
  <xacro:property name="M_PI" value="3.14159"/>

  <!-- Shoulder pan link properties -->
  <xacro:property name="shoulder_pan_width" value="0.042" />
  <xacro:property name="shoulder_pan_len" value="0.06" /> 
  <xacro:property name="shoulder_pan_height" value="0.09"/>


  <!-- Shoulder pitch link properties -->
  <xacro:property name="shoulder_pitch_len" value="0.08" />
  <xacro:property name="shoulder_pitch_width" value="0.057" />
  <xacro:property name="shoulder_pitch_height" value="0.025" />


  <!-- Elbow pitch link properties -->
  <xacro:property name="elbow_pitch_len" value="0.05" />
  <xacro:property name="elbow_pitch_width" value="0.025" />
  <xacro:property name="elbow_pitch_height" value="0.057" />

  <!-- Elbow roll link properties -->
  <xacro:property name="elbow_roll_len" value="0.15" />
  <xacro:property name="elbow_roll_width" value="0.025" />
  <xacro:property name="elbow_roll_height" value="0.08" />

  <!-- wrist pitch link properties -->
  <xacro:property name="wrist_pitch_len" value="0.07" />
  <xacro:property name="wrist_pitch_width" value="0.025" />
  <xacro:property name="wrist_pitch_height" value="0.057" />


  <!-- Gripper roll link properties -->
  <xacro:property name="gripper_roll_width" value="0.05" />
  <xacro:property name="gripper_roll_height" value="0.04" />
  <xacro:property name="gripper_roll_len" value="0.075" />


  <!-- Left gripper -->
  <xacro:property name="left_gripper_len" value="0.07" />
  <xacro:property name="left_gripper_width" value="0.01" />
  <xacro:property name="left_gripper_height" value="0.01" />


  <!-- Right gripper -->
  <xacro:property name="right_gripper_len" value="0.07" />
  <xacro:property name="right_gripper_width" value="0.01" />
  <xacro:property name="right_gripper_height" value="0.01" />



  <!-- Right gripper -->
  <xacro:property name="grasp_frame_len" value="0.02" />
  <xacro:property name="grasp_frame_width" value="0.02" />
  <xacro:property name="grasp_frame_height" value="0.02" />


   <xacro:macro name="inertial_matrix" params="mass">
      <inertial>
      	<mass value="${mass}" />
        <inertia ixx="1.0" ixy="0.0" ixz="0.0" iyy="0.5" iyz="0.0" izz="1.0" />
      </inertial>
   </xacro:macro>

   <xacro:macro name="transmission_block" params="joint_name">
	  <transmission name="tran1">
	    <type>transmission_interface/SimpleTransmission</type>
	    <joint name="${joint_name}">
	      <hardwareInterface>hardware_interface/PositionJointInterface</hardwareInterface>
	    </joint>
	    <actuator name="motor1">
	      <hardwareInterface>hardware_interface/PositionJointInterface</hardwareInterface>
	      <mechanicalReduction>1</mechanicalReduction>
	    </actuator>
	  </transmission>
   </xacro:macro>


<!-- BOTTOM FIXED LINK 
This link is the base of the arm in which arm is placed 

-->

<!-- ///////////////////////////////////////////////////////////////////////////////////////////////////////////////////// -->

  <joint name="bottom_joint" type="fixed">
    <origin xyz="0.08 0 0.01" rpy="0 0 0" />
    <parent link="bottom_link"/>
    <child link="base_link"/>
  </joint>

  <link name="bottom_link">

    <visual>
      <origin xyz=" 0 0 0"  rpy="0 0 0"/>
      <geometry>

          <box size ="0.25 0.45 0.01"/>

      </geometry>
      <material name="White" />
    </visual>

    <collision>
      <origin xyz=" 0 0 0"  rpy="0 0 0"/>
      <geometry>
          <box size ="0.25 0.45 0.01"/>
      </geometry>
      </collision>>

  </link>

  <gazebo reference="bottom_link">
    <material>Gazebo/White</material>
  </gazebo>


<!-- ///////////////////////////////////////////////////////////////////////////////////////////////////////////////////// -->

  <!-- BASE LINK -->
  <link name="base_link">

    <visual>
      <origin xyz="0 0 0.014" rpy="0 0 0" /> <!-- rotate PI/2 -->
      <geometry>

	       <box size="0.09 0.09 0.028" />

      </geometry>
      <material name="Black" />
    </visual>

    <collision>
      <origin xyz="0 0 0.014" rpy="0 0 0" /> <!-- rotate PI/2 -->
      <geometry>

	       <box size="0.09 0.09 0.028" />
		
      </geometry>
      </collision>>
	<xacro:inertial_matrix mass="1"/>

  </link>

  <gazebo reference="base_link">
    <material>Gazebo/Black</material>
  </gazebo>

  <joint name="shoulder_pan_joint" type="revolute">
    <parent link="base_link"/>
    <child link="shoulder_pan_link"/>
    <origin xyz="0 0 0.028" rpy="0 0 0" />
    <axis xyz="0 0 1" />
    <limit effort="300" velocity="1" lower="-${M_PI*95/180}" upper="${M_PI*85/180}"/>
    <dynamics damping="50" friction="1"/>
  </joint>


<!-- ///////////////////////////////////////////////////////////////////////////////////////////////////////////////////// -->

  <!-- SHOULDER PAN LINK -->
  <link name="shoulder_pan_link" >

    <visual>
      <origin xyz="0 0 0.045" rpy="0 0 0" />
      <geometry>

	<box size="${shoulder_pan_len} ${shoulder_pan_width} ${shoulder_pan_height}" />            

      </geometry>
      <material name="Red" />
    </visual>

    <collision>
      <origin xyz="0 0 0.045" rpy="0 0 0" />
      <geometry>
            <box size="${shoulder_pan_len} ${shoulder_pan_width} ${shoulder_pan_height}" />
      </geometry>
    </collision>
	<xacro:inertial_matrix mass="1"/>
  </link>

  <gazebo reference="shoulder_pan_link">
    <material>Gazebo/Red</material>
  </gazebo>

  <joint name="shoulder_pitch_joint" type="revolute">
    <parent link="shoulder_pan_link"/>
    <child link="shoulder_pitch_link"/>
    <origin xyz="0 0 0.09" rpy="0 0 0" />
    <axis xyz="0 1 0" />
    <limit effort="300" velocity="1" lower="-${M_PI/2}" upper="${M_PI/2}" />
    <dynamics damping="50" friction="1"/>
  </joint>

<!-- ///////////////////////////////////////////////////////////////////////////////////////////////////////////////////// -->
  <!-- SHOULDER PITCH LINK -->
  <link name="shoulder_pitch_link" >

    <visual>
      <origin xyz="0.0 0 0.04" rpy="${M_PI/2} ${M_PI/2} ${M_PI/2}" />
      <geometry>

           <box size="${shoulder_pitch_len} ${shoulder_pitch_width} ${shoulder_pitch_height}" />

      </geometry>
      <material name="White" />
    </visual>

    <collision>
      <origin xyz="0.0 0 0.04" rpy="${M_PI/2} ${M_PI/2} ${M_PI/2}" />
      <geometry>
           <box size="${shoulder_pitch_len} ${shoulder_pitch_width} ${shoulder_pitch_height}" />
      </geometry>
    </collision>
	<xacro:inertial_matrix mass="1"/>
  </link>

  <gazebo reference="shoulder_pitch_link">
    <material>Gazebo/White</material>
  </gazebo>

  <joint name="elbow_pitch_joint" type="revolute">
    <parent link="shoulder_pitch_link"/>
    <child link="elbow_pitch_link"/>
    <origin xyz="0 0 0.08" rpy="0 0 0" />
    <axis xyz="0 -1 0" />
    <limit effort="300" velocity="1" lower="-${M_PI/2}" upper="${M_PI/2}" />
    <dynamics damping="50" friction="1"/>
  </joint>

<!-- ///////////////////////////////////////////////////////////////////////////////////////////////////////////////////// -->

  <!-- ELBOW PITCH LINK -->
  <link name="elbow_pitch_link" >

    <visual>
      <origin xyz="0 0 0.025" rpy="${M_PI/2} ${M_PI/2} 0" />
      <geometry>

       <box size="${elbow_pitch_len} ${elbow_pitch_width} ${elbow_pitch_height}" />
	
      </geometry>
      <material name="Red" />
    </visual>

    <collision>
      <origin xyz="0 0 0.025" rpy="${M_PI/2} ${M_PI/2} 0" />
      <geometry>
       <box size="${elbow_pitch_len} ${elbow_pitch_width} ${elbow_pitch_height}" />
      </geometry>
    </collision>
	<xacro:inertial_matrix mass="1"/>
  </link>

  <gazebo reference="elbow_pitch_link">
    <material>Gazebo/Red</material>
  </gazebo>


  <!-- ELBOW ROLL LINK -->
  <joint name="elbow_roll_joint" type="revolute">
    <parent link="elbow_pitch_link"/>
    <child link="elbow_roll_link"/>
    <origin xyz="0.0 0.00 0.050" rpy="0 0 0" />
    <axis xyz="0 0 1" />
    <limit effort="300" velocity="1" lower="-${M_PI*85/180}" upper="${M_PI*95/180}" />
    <dynamics damping="50" friction="1"/>
</joint>

  <link name="elbow_roll_link" >

    <visual>
      <origin xyz="0 0 0.075" rpy="${M_PI/2} ${M_PI/2} 0" />
      <geometry>

       <box size="${elbow_roll_len} ${elbow_roll_width} ${elbow_roll_height}" />
	
      </geometry>
      <material name="White" />
    </visual>

    <collision>
      <origin xyz="0 0 0.075" rpy="${M_PI/2} ${M_PI/2} 0" />
      <geometry>
       <box size="${elbow_roll_len} ${elbow_roll_width} ${elbow_roll_height}" />
      </geometry>
    </collision>
	<xacro:inertial_matrix mass="1"/>
  </link>

  <gazebo reference="elbow_roll_link">
    <material>Gazebo/White</material>
  </gazebo>

  <joint name="wrist_pitch_joint" type="revolute">
    <parent link="elbow_roll_link"/>
    <child link="wrist_pitch_link"/>
    <origin xyz="0.0 0.00 0.150" rpy="0 0 0" />
    <axis xyz="0 1 0" />
    <limit effort="300" velocity="1" lower="-${M_PI*4/9}" upper="${M_PI*5/9}" />
    <dynamics damping="50" friction="1"/>
  </joint>

  <!-- WRIST PITCH LINK -->
  <link name="wrist_pitch_link" >
    <visual>
      <origin xyz="0 0 0.035" rpy="0 ${M_PI/2} ${M_PI/2}" />
      <geometry>
	<box size="${wrist_pitch_len} ${wrist_pitch_width} ${wrist_pitch_height}" />
      </geometry>
      <material name="Black" />
    </visual>

    <collision>
      <origin xyz="0 0 0.035" rpy="0 ${M_PI/2} ${M_PI/2}" />
      <geometry>
           <box size="${wrist_pitch_len} ${wrist_pitch_width} ${wrist_pitch_height}" />
      </geometry>
    </collision>
	<xacro:inertial_matrix mass="1"/>

  </link>

  <gazebo reference="wrist_pitch_link">
    <material>Gazebo/White</material>
  </gazebo>

  <joint name="gripper_roll_joint" type="revolute">
    <parent link="wrist_pitch_link"/>
    <child link="gripper_roll_link"/>
    <origin xyz="0 0 0.07" rpy="0 0  ${M_PI/2}" />
    <axis xyz="0 0 1" />
    <!--
		<limit effort="300" velocity="1" lower="-2.61799387799" upper="2.6128806087" />
		-->
		<limit effort="300" velocity="1" lower="0" upper="${M_PI}" />
    <dynamics damping="50" friction="1"/>
  </joint>

<!-- ///////////////////////////////////////////////////////////////////////////////////////////////////////////////////// -->

  <!-- GRIPPER ROLL LINK -->
  <link name="gripper_roll_link">

    <visual>
      <origin xyz="-0.025 -0.015 0.02" rpy="0 0 0" />
      <geometry>

          <box size="${gripper_roll_len} ${gripper_roll_width} ${gripper_roll_height}"/>
            <!-- <radius="${gripper_roll_width}" length="${gripper_roll_len}"/> -->

      </geometry>
      <material name="Red" />
    </visual>

    <collision>
      <origin xyz="-0.03 -0.01 0.025" rpy="0 0 0" />
      <geometry>
	    <box size="${gripper_roll_len} ${gripper_roll_width} ${gripper_roll_height}" />
      </geometry>
    </collision>
	<xacro:inertial_matrix mass="1"/>

  </link>

  <gazebo reference="gripper_roll_link">
    <material>Gazebo/Red</material>
  </gazebo>


  <!--joint name="finger_joint1" type="prismatic">
    <parent link="gripper_roll_link"/>
    <child link="gripper_finger_link1"/>
    <origin xyz="0 0 0.01" />
    <axis xyz="1 0 0" />
      <limit effort="100" lower="0" upper="0.025" velocity="1.0"/>


      <safety_controller k_position="20"
                         k_velocity="20"
                         soft_lower_limit="${-0.15 }"
                         soft_upper_limit="${ 0.0 }"/>


    <dynamics damping="50" friction="1"/>
  </joint -->


<!-- ///////////////////////////////////////////////////////////////////////////////////////////////////////////////////// -->


  <!-- LEFT GRIPPER AFT LINK -->
  <link name="gripper_finger_link1">

     <visual>
      <origin xyz="0.0 0 0.035" rpy="0 ${M_PI/2} 0"/>
      <geometry>

           <box size="${left_gripper_len} ${left_gripper_width} ${left_gripper_height}" />

      </geometry>
      <material name="Black" />
    </visual>
	<xacro:inertial_matrix mass="1"/>
  </link>

  <gazebo reference="l_gripper_aft_link">
    <material>Gazebo/Black</material>
  </gazebo>

<!-- Joint between Wrist roll and finger 1 -->

  <joint name="finger_joint1" type="prismatic">
    <parent link="gripper_roll_link"/>
    <child link="gripper_finger_link1"/>
    <origin xyz="0.0 0.0 0.04" />
    <axis xyz="1 0 0" />
    <limit effort="1" lower="0" upper="0.025" velocity="1.0"/>

<!--    <mimic joint="gripper_finger_joint" multiplier="-1.0" offset="0.0" /> -->

    <dynamics damping="50" friction="1"/>
  </joint>


  <!-- RIGHT GRIPPER AFT LINK -->


  <link name="gripper_finger_link2">
    <visual>
      <origin xyz="0.0 0 0.035" rpy="0 ${M_PI/2} 0"/>
      <geometry>
      	<box size="${right_gripper_len} ${right_gripper_width} ${right_gripper_height}" />
      </geometry>
      <material name="Black" />
    </visual>
	<xacro:inertial_matrix mass="1"/>
  </link>

  <gazebo reference="r_gripper_aft_link">
    <material>Gazebo/Black</material>
  </gazebo>

<!-- Joint between Wrist roll and finger 2 -->

  <joint name="finger_joint2" type="prismatic">
    <parent link="gripper_roll_link"/>
    <child link="gripper_finger_link2"/>
    <origin xyz="0.0 0.00 0.04" />
    <axis xyz="1 0 0" />
    <limit effort="1" lower="-0.025" upper="0" velocity="1.0"/>

<!--    <mimic joint="gripper_finger_joint" multiplier="-1.0" offset="0.0" /> -->

    <dynamics damping="50" friction="1"/>
  </joint> 

    <!-- Grasping frame -->
    <!-- link name="grasping_frame">

      <inertial>
        <origin xyz="0 0 0" rpy="0 0 0"/>
        <mass value="0.0001"/>
        <cuboid_inertia mass="0.0001" x="0.001" y="0.001" z="0.001"/>
        <inertia  ixx="1.0" ixy="0.0"  ixz="0.0"  iyy="100.0"  iyz="0.0"  izz="1.0" />

      </inertial>

    <visual>
      <origin xyz="0 0 0"/>
      <geometry>
					
          <box size="${grasp_frame_len} ${grasp_frame_width} ${grasp_frame_height}" />
					
      </geometry>
      <material name="White" />
    </visual>

    </link>
	
    <joint name="grasping_frame_joint" type="fixed">
      <parent link="gripper_roll_link"/>
      <child link="grasping_frame"/>
      <origin xyz="0.08 0 0" rpy="0 0 0"/>
    </joint-->
		
  <xacro:include filename="$(find six_dof_arm_pkg)/config/sensors/xtion_pro_live.urdf.xacro"/>



  <!-- Transmissions for ROS Control -->

   <xacro:transmission_block joint_name="shoulder_pan_joint"/>
   <xacro:transmission_block joint_name="shoulder_pitch_joint"/>
   <xacro:transmission_block joint_name="elbow_pitch_joint"/>
   <xacro:transmission_block joint_name="elbow_roll_joint"/>
   <xacro:transmission_block joint_name="wrist_pitch_joint"/>
   <xacro:transmission_block joint_name="gripper_roll_joint"/>
   <xacro:transmission_block joint_name="finger_joint1"/>
   <xacro:transmission_block joint_name="finger_joint2"/>
	
 <!-- ros_control plugin -->
  <gazebo>
    <plugin name="gazebo_ros_control" filename="libgazebo_ros_control.so">
      <robotNamespace>/six_dof_arm</robotNamespace>
    </plugin>
  </gazebo>

    <!-- Links to Kinect -->

  <link name="kinect_link">

    <visual>
      <origin xyz=" 0 0 0.5"  rpy="0 0 0"/>
      <geometry>

           <box size="0.02 0.02 1.0" />

      </geometry>
      <material name="White" />
    </visual>

    <collision>
      <origin xyz="0 0.0 0.5"  rpy="0 0 0"/>
      <geometry>
           <box size="0.02 0.02 1.0" />
      </geometry>
      </collision>>

    <xacro:inertial_matrix mass="1"/>
  </link>

  <joint name="kinect_joint" type="fixed">
    <origin xyz="-0.04 0.16 0.01" rpy="0 0 0" />
    <parent link="bottom_link"/>
    <child link="kinect_link"/>
  </joint>
      
  <gazebo reference="kinect_link">
    <material>Gazebo/White</material>
  </gazebo>
 
  <link name="kinect_link2">

    <visual>
      <origin xyz=" 0 0 0.5"  rpy="0 0 0"/>
      <geometry>

           <box size="0.02 0.02 1.0" />

      </geometry>
      <material name="White" />
    </visual>

    <collision>
      <origin xyz="0 0.0 0.5"  rpy="0 0 0"/>
      <geometry>
           <box size="0.02 0.02 1.0" />
      </geometry>
      </collision>>

    <xacro:inertial_matrix mass="1"/>
  </link>

  <joint name="kinect_joint2" type="fixed">
    <origin xyz="-0.04 -0.16 0.0" rpy="0 0 0" />
    <parent link="bottom_link"/>
    <child link="kinect_link2"/>
  </joint>
      
  <gazebo reference="kinect_link">
    <material>Gazebo/White</material>
  </gazebo>

  <xacro:xtion_pro_live name="rgbd_camera" parent="kinect">
          <origin xyz="0.02 -0.11 1.0" rpy="0 ${90.0 * deg_to_rad} 0"/> <!--100cm high,5cm backward 75 deg angle downwards -->
    <origin xyz="0 0 0" rpy="${-90.0 * deg_to_rad} 0 ${-90.0 * deg_to_rad}"/>
  </xacro:xtion_pro_live>


</robot>
